Workbook

Sheet Colaboradores
A1: Codigo | B1: Nombre | C1: Correo | D1: CURP | E1: JefeCodigo | F1: Area | G1: Departamento | H1: Categoria | I1: DiasAsignados | J1: FechaIngreso | K1: EsRRHH | L1: Puesto
A2: 10001 | B2: NANCY JANET GOMEZ RUIZ | C2: ngomez@cafepuntadelcielo.co | D2: GORN8008076X7 | E2: ANA LILIA MENDOZA TORRES | F2: FINANZAS | G2: CUENTAS POR COBRAR | H2: ADMINISTRATIVO | I2: 52 | J2: 26/02/2008 | L2: =IF($B2="","",IFERROR(_xlfn.XLOOKUP(_xlfn.TEXTJOIN(" ",TRUE,_xlfn._xlws.SORT(_xlfn.TEXTSPLIT(TRIM(UPPER($B2))," ",,TRUE),1,1,TRUE)),puestos!$C$2:$C$324,puestos!$B$2:$B$324),"SIN PUESTO")) -> COORDINADOR CUENTAS POR COBRAR
A3: 10002 | B3: MANUEL JAVIER VILLEDA MORENO | D3: VIMM691203AW6 | E3: NEIDY MARTINEZ MARTINEZ | F3: MANUFACTURA | G3: ARQUITECTURA | H3: OPERATIVO | I3: 58 | J3: 19/10/2009 | L3: =IF($B3="","",IFERROR(_xlfn.XLOOKUP(_xlfn.TEXTJOIN(" ",TRUE,_xlfn._xlws.SORT(_xlfn.TEXTSPLIT(TRIM(UPPER($B3))," ",,TRUE),1,1,TRUE)),puestos!$C$2:$C$324,puestos!$B$2:$B$324),"SIN PUESTO")) -> AUXILIAR DE MANTENIMIENTO
A4: 10003 | B4: JOSE FELIX FLORES ROJAS | D4: FORF650530RA3 | E4: NEIDY MARTINEZ MARTINEZ | F4: LOGISTICA & OPERACIONES | G4: ARQUITECTURA | H4: OPERATIVO | I4: 48 | J4: 16/06/2011 | L4: =IF($B4="","",IFERROR(_xlfn.XLOOKUP(_xlfn.TEXTJOIN(" ",TRUE,_xlfn._xlws.SORT(_xlfn.TEXTSPLIT(TRIM(UPPER($B4))," ",,TRUE),1,1,TRUE)),puestos!$C$2:$C$324,puestos!$B$2:$B$324),"SIN PUESTO")) -> AUXILIAR DE INFRAESTRUCTURA
A5: 10004 | B5: ELIA CRESCENCIO ESQUIVEL | C5: ecrescencio@cafepuntadelcielo.co | D5: CEEE7905108E7 | E5: EDGAR ALVAREZ RIOS | F5: FINANZAS | G5: CONTABILIDAD | H5: ADMINISTRATIVO | I5: 70 | J5: 12/10/2012 | L5: =IF($B5="","",IFERROR(_xlfn.XLOOKUP(_xlfn.TEXTJOIN(" ",TRUE,_xlfn._xlws.SORT(_xlfn.TEXTSPLIT(TRIM(UPPER($B5))," ",,TRUE),1,1,TRUE)),puestos!$C$2:$C$324,puestos!$B$2:$B$324),"SIN PUESTO")) -> ANALISTA CONTABLE
A6: 10005 | B6: JOSE ANTONIO MARTINEZ MARTINEZ | C6: jmmartinez@cafepuntadelcielo.co | D6: MAMA690525TBA | E6: EDGAR ALVAREZ RIOS | F6: FINANZAS | G6: CONTABILIDAD | H6: ADMINISTRATIVO | I6: 36 | J6: 20/03/2013 | L6: =IF($B6="","",IFERROR(_xlfn.XLOOKUP(_xlfn.TEXTJOIN(" ",TRUE,_xlfn._xlws.SORT(_xlfn.TEXTSPLIT(TRIM(UPPER($B6))," ",,TRUE),1,1,TRUE)),puestos!$C$2:$C$324,puestos!$B$2:$B$324),"SIN PUESTO")) -> ANALISTA CONTABLE
A7: 10006 | B7: EDUARDO CAMACHO MEDINA | C7: emedina@cafepuntadelcielo.co | D7: CAME690120RT2 | E7: ABRAHAM ISAIAS PADRON CASTRO | F7: LOGISTICA & OPERACIONES | G7: LOGISTICA | H7: ADMINISTRATIVO | I7: 35 | J7: 09/04/2013 | L7: =IF($B7="","",IFERROR(_xlfn.XLOOKUP(_xlfn.TEXTJOIN(" ",TRUE,_xlfn._xlws.SORT(_xlfn.TEXTSPLIT(TRIM(UPPER($B7))," ",,TRUE),1,1,TRUE)),puestos!$C$2:$C$324,puestos!$B$2:$B$324),"SIN PUESTO")) -> ESPECIALISTA CONTABLE
A8: 10007 | B8: ADRIANA GARCIA PARRA | C8: agparra@cafepuntadelcielo.co | D8: GAPA7603051T9 | E8: JOAQUIN CURIEL SANCHEZ | F8: LOGISTICA & OPERACIONES | G8: SERVICIO AL CLIENTE | H8: ADMINISTRATIVO | I8: 48 | J8: 01/08/2013 | L8: =IF($B8="","",IFERROR(_xlfn.XLOOKUP(_xlfn.TEXTJOIN(" ",TRUE,_xlfn._xlws.SORT(_xlfn.TEXTSPLIT(TRIM(UPPER($B8))," ",,TRUE),1,1,TRUE)),puestos!$C$2:$C$324,puestos!$B$2:$B$324),"SIN PUESTO")) -> COORDINADOR SAC
A9: 10008 | B9: NEIDY MARTINEZ MARTINEZ | C9: neidym@cafepuntadelcielo.co | D9: MAMN771201UV0 | E9: ALBIN SAMUEL GOMEZ PINZON | F9: GENTE & GESTION | G9: GENTE Y GESTION | H9: ADMINISTRATIVO | I9: 50 | J9: 04/11/2013 | L9: =IF($B9="","",IFERROR(_xlfn.XLOOKUP(_xlfn.TEXTJOIN(" ",TRUE,_xlfn._xlws.SORT(_xlfn.TEXTSPLIT(TRIM(UPPER($B9))," ",,TRUE),1,1,TRUE)),puestos!$C$2:$C$324,puestos!$B$2:$B$324),"SIN PUESTO")) -> ANALISTA DE SERVICIOS GENERALES
A10: 10009 | B10: ANAYELI GARCIA MINGOLE | C10: amingole@cafepuntadelcielo.co | D10: GAMA880627D13 | E10: ALBIN SAMUEL GOMEZ PINZON | F10: GENTE & GESTION | G10: GENTE Y GESTIÓN PLANTA | H10: ADMINISTRATIVO | I10: 61 | J10: 14/07/2014 | K10: SI | L10: =IF($B10="","",IFERROR(_xlfn.XLOOKUP(_xlfn.TEXTJOIN(" ",TRUE,_xlfn._xlws.SORT(_xlfn.TEXTSPLIT(TRIM(UPPER($B10))," ",,TRUE),1,1,TRUE)),puestos!$C$2:$C$324,puestos!$B$2:$B$324),"SIN PUESTO")) -> JEFE DE G&G
A11: 10010 | B11: ALMA DELIA HERRERA VAZQUEZ | C11: advazquez@cafepuntadelcielo.co | D11: HEVA891006NJA | E11: ARMANDO RODRIGUEZ NAVARRETE | F11: MANUFACTURA | G11: ADMINISTRACION PLANTA | H11: ADMINISTRATIVO | I11: 42 | J11: 15/01/2015 | L11: =IF($B11="","",IFERROR(_xlfn.XLOOKUP(_xlfn.TEXTJOIN(" ",TRUE,_xlfn._xlws.SORT(_xlfn.TEXTSPLIT(TRIM(UPPER($B11))," ",,TRUE),1,1,TRUE)),puestos!$C$2:$C$324,puestos!$B$2:$B$324),"SIN PUESTO")) -> JEFE DE PRODUCCION
A12: 10011 | B12: CARMEN EDITH JIMENEZ DEL RAZO | C12: cjrazo@cafepuntadelcielo.co | D12: JIRC921129R29 | E12: HUGO CESAR GARCIA PEREZ | F12: LEGAL | G12: JURIDICO | H12: ADMINISTRATIVO | I12: 44 | J12: 20/12/2016 | L12: =IF($B12="","",IFERROR(_xlfn.XLOOKUP(_xlfn.TEXTJOIN(" ",TRUE,_xlfn._xlws.SORT(_xlfn.TEXTSPLIT(TRIM(UPPER($B12))," ",,TRUE),1,1,TRUE)),puestos!$C$2:$C$324,puestos!$B$2:$B$324),"SIN PUESTO")) -> JEFE DE SOSTENIBILIDAD
A13: 10012 | B13: CARLOS CALIXTRO HERNANDEZ | C13: ccalixtro@cafepuntadelcielo.co | D13: CAHC670821SS2 | E13: DIEGO ARMANDO SANCHEZ OJEDA | F13: LOGISTICA & OPERACIONES | G13: LOGISTICA | H13: ADMINISTRATIVO | I13: 34 | J13: 22/05/2017 | L13: =IF($B13="","",IFERROR(_xlfn.XLOOKUP(_xlfn.TEXTJOIN(" ",TRUE,_xlfn._xlws.SORT(_xlfn.TEXTSPLIT(TRIM(UPPER($B13))," ",,TRUE),1,1,TRUE)),puestos!$C$2:$C$324,puestos!$B$2:$B$324),"SIN PUESTO")) -> COORDINADOR DE BODEGA
A14: 10013 | B14: CINTHIA PAOLA NEGRETE CHAVEZ | D14: NECC841216H29 | E14: NEIDY MARTINEZ MARTINEZ | F14: LOGISTICA & OPERACIONES | G14: INTENDENCIA | H14: OPERATIVO | I14: 27 | J14: 14/11/2017 | L14: =IF($B14="","",IFERROR(_xlfn.XLOOKUP(_xlfn.TEXTJOIN(" ",TRUE,_xlfn._xlws.SORT(_xlfn.TEXTSPLIT(TRIM(UPPER($B14))," ",,TRUE),1,1,TRUE)),puestos!$C$2:$C$324,puestos!$B$2:$B$324),"SIN PUESTO")) -> AUXILIAR DE LIMPIEZA
A15: 10014 | B15: ALEJANDRO MEDINA ORTEGA | C15: amortega@cafepuntadelcielo.co | D15: MEOA881117FB0 | E15: JOAQUIN CURIEL SANCHEZ | F15: LOGISTICA & OPERACIONES | G15: SERVICIO AL CLIENTE | H15: ADMINISTRATIVO | I15: 44 | J15: 07/04/2018 | L15: =IF($B15="","",IFERROR(_xlfn.XLOOKUP(_xlfn.TEXTJOIN(" ",TRUE,_xlfn._xlws.SORT(_xlfn.TEXTSPLIT(TRIM(UPPER($B15))," ",,TRUE),1,1,TRUE)),puestos!$C$2:$C$324,puestos!$B$2:$B$324),"SIN PUESTO")) -> COORDINADOR SAC
A16: 10015 | B16: ESTEPHANY COLIN MAYEN | C16: ecolin@cafepuntadelcielo.co | D16: COME920924JI3 | E16: LUIS ALBERTO MONTIEL MANSO | F16: MARKETING | G16: MARKETING | H16: ADMINISTRATIVO | I16: 24 | J16: 17/04/2018 | L16: =IF($B16="","",IFERROR(_xlfn.XLOOKUP(_xlfn.TEXTJOIN(" ",TRUE,_xlfn._xlws.SORT(_xlfn.TEXTSPLIT(TRIM(UPPER($B16))," ",,TRUE),1,1,TRUE)),puestos!$C$2:$C$324,puestos!$B$2:$B$324),"SIN PUESTO")) -> ESPECIALISTA DE MARKETING
A17: 10016 | B17: JOSE GERARDO SERVIN FLORES | D17: SEFG751021NF7 | E17: LIZBETH RODRIGUEZ RODRIGUEZ | F17: LOGISTICA & OPERACIONES | G17: LOGISTICA | H17: OPERATIVO | I17: 30 | J17: 29/05/2018 | L17: =IF($B17="","",IFERROR(_xlfn.XLOOKUP(_xlfn.TEXTJOIN(" ",TRUE,_xlfn._xlws.SORT(_xlfn.TEXTSPLIT(TRIM(UPPER($B17))," ",,TRUE),1,1,TRUE)),puestos!$C$2:$C$324,puestos!$B$2:$B$324),"SIN PUESTO")) -> CHOFER
A18: 10017 | B18: JORGE ANTONIO JIMENEZ UGALDE | C18: jajimenez@cafepuntadelcielo.co | D18: JIUJ880317H43 | E18: CARLOS ARTURO RODRIGUEZ MARCIA | F18: COMERCIAL | G18: COMERCIAL | H18: ADMINISTRATIVO | I18: 38 | J18: 04/03/2019 | L18: =IF($B18="","",IFERROR(_xlfn.XLOOKUP(_xlfn.TEXTJOIN(" ",TRUE,_xlfn._xlws.SORT(_xlfn.TEXTSPLIT(TRIM(UPPER($B18))," ",,TRUE),1,1,TRUE)),puestos!$C$2:$C$324,puestos!$B$2:$B$324),"SIN PUESTO")) -> GERENTE COMERCIAL
A19: 10018 | B19: CARLOS MONREAL MORAN | D19: MOMC751111B56 | E19: DIEGO ARMANDO SANCHEZ OJEDA | F19: LOGISTICA & OPERACIONES | G19: LOGISTICA | H19: OPERATIVO | I19: 44 | J19: 20/05/2019 | L19: =IF($B19="","",IFERROR(_xlfn.XLOOKUP(_xlfn.TEXTJOIN(" ",TRUE,_xlfn._xlws.SORT(_xlfn.TEXTSPLIT(TRIM(UPPER($B19))," ",,TRUE),1,1,TRUE)),puestos!$C$2:$C$324,puestos!$B$2:$B$324),"SIN PUESTO")) -> AUXILIAR DE BODEGA
A20: 10019 | B20: ALMA RANGEL AYALA | C20: arangel@cafepuntadelcielo.co | D20: RAAA730514SL7 | E20: LIZBETH RODRIGUEZ RODRIGUEZ | F20: LOGISTICA & OPERACIONES | G20: LOGISTICA | H20: ADMINISTRATIVO | I20: 44 | J20: 03/06/2019 | L20: =IF($B20="","",IFERROR(_xlfn.XLOOKUP(_xlfn.TEXTJOIN(" ",TRUE,_xlfn._xlws.SORT(_xlfn.TEXTSPLIT(TRIM(UPPER($B20))," ",,TRUE),1,1,TRUE)),puestos!$C$2:$C$324,puestos!$B$2:$B$324),"SIN PUESTO")) -> COORDINADOR DE TRANSPORTE
A21: 10020 | B21: GUSTAVO FITZ BLAS | C21: gfitz@cafepuntadelcielo.co | D21: FIBG870522PB0 | E21: JOAQUIN CURIEL SANCHEZ | F21: LOGISTICA & OPERACIONES | G21: SERVICIO AL CLIENTE | H21: ADMINISTRATIVO | I21: 44 | J21: 17/06/2019 | L21: =IF($B21="","",IFERROR(_xlfn.XLOOKUP(_xlfn.TEXTJOIN(" ",TRUE,_xlfn._xlws.SORT(_xlfn.TEXTSPLIT(TRIM(UPPER($B21))," ",,TRUE),1,1,TRUE)),puestos!$C$2:$C$324,puestos!$B$2:$B$324),"SIN PUESTO")) -> COORDINADOR SAC
A22: 10021 | B22: OSCAR RAMON MENDOZA CAMACHO | D22: MECO8912101A7 | E22: LIZBETH RODRIGUEZ RODRIGUEZ | F22: LOGISTICA & OPERACIONES | G22: LOGISTICA | H22: OPERATIVO | I22: 44 | J22: 15/07/2019 | L22: =IF($B22="","",IFERROR(_xlfn.XLOOKUP(_xlfn.TEXTJOIN(" ",TRUE,_xlfn._xlws.SORT(_xlfn.TEXTSPLIT(TRIM(UPPER($B22))," ",,TRUE),1,1,TRUE)),puestos!$C$2:$C$324,puestos!$B$2:$B$324),"SIN PUESTO")) -> CHOFER
A23: 10022 | B23: MARCO ANTONIO RUIZ MORALES | D23: RUMM751230198 | E23: LIZBETH RODRIGUEZ RODRIGUEZ | F23: LOGISTICA & OPERACIONES | G23: LOGISTICA | H23: OPERATIVO | I23: 37 | J23: 12/08/2019 | L23: =IF($B23="","",IFERROR(_xlfn.XLOOKUP(_xlfn.TEXTJOIN(" ",TRUE,_xlfn._xlws.SORT(_xlfn.TEXTSPLIT(TRIM(UPPER($B23))," ",,TRUE),1,1,TRUE)),puestos!$C$2:$C$324,puestos!$B$2:$B$324),"SIN PUESTO")) -> CHOFER
A24: 10023 | B24: ANDRES PEREZ ABAD | C24: aabad@cafepuntadelcielo.co | D24: PEAA891012GJ2 | E24: EDGAR ALVAREZ RIOS | F24: FINANZAS | G24: CONTABILIDAD | H24: ADMINISTRATIVO | I24: 44 | J24: 19/08/2019 | L24: =IF($B24="","",IFERROR(_xlfn.XLOOKUP(_xlfn.TEXTJOIN(" ",TRUE,_xlfn._xlws.SORT(_xlfn.TEXTSPLIT(TRIM(UPPER($B24))," ",,TRUE),1,1,TRUE)),puestos!$C$2:$C$324,puestos!$B$2:$B$324),"SIN PUESTO")) -> ANALISTA CONTABLE
A25: 10024 | B25: DANIEL MACIAS PREZA | C25: dmacias@cafepuntadelcielo.co | D25: MAPD920915PN0 | E25: EDGAR ALVAREZ RIOS | F25: FINANZAS | G25: CONTABILIDAD | H25: ADMINISTRATIVO | I25: 33 | J25: 26/08/2019 | L25: =IF($B25="","",IFERROR(_xlfn.XLOOKUP(_xlfn.TEXTJOIN(" ",TRUE,_xlfn._xlws.SORT(_xlfn.TEXTSPLIT(TRIM(UPPER($B25))," ",,TRUE),1,1,TRUE)),puestos!$C$2:$C$324,puestos!$B$2:$B$324),"SIN PUESTO")) -> COORDINADOR CONTABLE
A26: 10025 | B26: DIEGO ARMANDO SANCHEZ OJEDA | C26: dasanchez@cafepuntadelcielo.co | D26: SAOD840706NI0 | E26: DAVID ARTURO DIAZ RAMIREZ | F26: LOGISTICA & OPERACIONES | G26: LOGISTICA | H26: ADMINISTRATIVO | I26: 37 | J26: 26/08/2019 | L26: =IF($B26="","",IFERROR(_xlfn.XLOOKUP(_xlfn.TEXTJOIN(" ",TRUE,_xlfn._xlws.SORT(_xlfn.TEXTSPLIT(TRIM(UPPER($B26))," ",,TRUE),1,1,TRUE)),puestos!$C$2:$C$324,puestos!$B$2:$B$324),"SIN PUESTO")) -> JEFE DE BODEGA
A27: 10026 | B27: JAZMIN VAZQUEZ CRUZ | C27: jvcruz@cafepuntadelcielo.co | D27: VACJ931002HA7 | E27: ANA LILIA MENDOZA TORRES | F27: FINANZAS | G27: CUENTAS POR COBRAR | H27: ADMINISTRATIVO | I27: 64 | J27: 26/11/2019 | L27: =IF($B27="","",IFERROR(_xlfn.XLOOKUP(_xlfn.TEXTJOIN(" ",TRUE,_xlfn._xlws.SORT(_xlfn.TEXTSPLIT(TRIM(UPPER($B27))," ",,TRUE),1,1,TRUE)),puestos!$C$2:$C$324,puestos!$B$2:$B$324),"SIN PUESTO")) -> ANALISTA CUENTAS POR PAGAR
A28: 10027 | B28: IVONNE BADILLO TORRES | C28: ibadillo@cafepuntadelcielo.co | D28: BATI930823UTA | E28: LUIS ANTONIO SANTOS HERNANDEZ | F28: GENTE & GESTION | G28: GENTE Y GESTION | H28: ADMINISTRATIVO | I28: 19 | J28: 04/02/2020 | L28: =IF($B28="","",IFERROR(_xlfn.XLOOKUP(_xlfn.TEXTJOIN(" ",TRUE,_xlfn._xlws.SORT(_xlfn.TEXTSPLIT(TRIM(UPPER($B28))," ",,TRUE),1,1,TRUE)),puestos!$C$2:$C$324,puestos!$B$2:$B$324),"SIN PUESTO")) -> COORDINADOR DE NOMINA
A29: 10028 | B29: VICTOR HUGO LOPEZ HERNANDEZ | D29: LOHV861204G12 | E29: DIEGO ARMANDO SANCHEZ OJEDA | F29: LOGISTICA & OPERACIONES | G29: LOGISTICA | H29: OPERATIVO | I29: 29 | J29: 24/02/2020 | L29: =IF($B29="","",IFERROR(_xlfn.XLOOKUP(_xlfn.TEXTJOIN(" ",TRUE,_xlfn._xlws.SORT(_xlfn.TEXTSPLIT(TRIM(UPPER($B29))," ",,TRUE),1,1,TRUE)),puestos!$C$2:$C$324,puestos!$B$2:$B$324),"SIN PUESTO")) -> AUXILIAR DE BODEGA
A30: 10029 | B30: LUIS FELIPE ROMAN NONOAL | C30: lroman@cafeportales.com | D30: RONL9303013C0 | E30: LUIS ANTONIO SANTOS HERNANDEZ | F30: GENTE & GESTION | G30: GENTE Y GESTION | H30: ADMINISTRATIVO | I30: 22 | J30: 06/04/2020 | L30: =IF($B30="","",IFERROR(_xlfn.XLOOKUP(_xlfn.TEXTJOIN(" ",TRUE,_xlfn._xlws.SORT(_xlfn.TEXTSPLIT(TRIM(UPPER($B30))," ",,TRUE),1,1,TRUE)),puestos!$C$2:$C$324,puestos!$B$2:$B$324),"SIN PUESTO")) -> COORDINADOR DE NOMINA
A31: 10030 | B31: ALEJANDRA BERENICE DAVID CAMACHO | C31: adavid@cafepuntadelcielo.co | D31: DACA900723S81 | E31: LUIS ALBERTO MONTIEL MANSO | F31: MARKETING | G31: MARKETING | H31: ADMINISTRATIVO | I31: 40 | J31: 06/11/2020 | L31: =IF($B31="","",IFERROR(_xlfn.XLOOKUP(_xlfn.TEXTJOIN(" ",TRUE,_xlfn._xlws.SORT(_xlfn.TEXTSPLIT(TRIM(UPPER($B31))," ",,TRUE),1,1,TRUE)),puestos!$C$2:$C$324,puestos!$B$2:$B$324),"SIN PUESTO")) -> ESPECIALISTA DE DISEÑO GRAFICO
A32: 10031 | B32: MAYRA SOFIA BARON ROJAS | C32: mbaron@cafepuntadelcielo.co | D32: BARM750918IF9 | E32: DIEGO ARMANDO SANCHEZ OJEDA | F32: LOGISTICA & OPERACIONES | G32: LOGISTICA | H32: ADMINISTRATIVO | I32: 42 | J32: 09/12/2020 | L32: =IF($B32="","",IFERROR(_xlfn.XLOOKUP(_xlfn.TEXTJOIN(" ",TRUE,_xlfn._xlws.SORT(_xlfn.TEXTSPLIT(TRIM(UPPER($B32))," ",,TRUE),1,1,TRUE)),puestos!$C$2:$C$324,puestos!$B$2:$B$324),"SIN PUESTO")) -> VERIFICADOR
A33: 10032 | B33: JOAQUIN RODRIGUEZ CORONA | D33: ROCJ7105068A0 | E33: LIZBETH RODRIGUEZ RODRIGUEZ | F33: LOGISTICA & OPERACIONES | G33: LOGISTICA | H33: OPERATIVO | I33: 14 | J33: 20/01/2021 | L33: =IF($B33="","",IFERROR(_xlfn.XLOOKUP(_xlfn.TEXTJOIN(" ",TRUE,_xlfn._xlws.SORT(_xlfn.TEXTSPLIT(TRIM(UPPER($B33))," ",,TRUE),1,1,TRUE)),puestos!$C$2:$C$324,puestos!$B$2:$B$324),"SIN PUESTO")) -> CHOFER
A34: 10033 | B34: FERNANDO REYES SANCHEZ | D34: RESF850802T65 | E34: LIZBETH RODRIGUEZ RODRIGUEZ | F34: LOGISTICA & OPERACIONES | G34: LOGISTICA | H34: OPERATIVO | I34: 36 | J34: 08/04/2021 | L34: =IF($B34="","",IFERROR(_xlfn.XLOOKUP(_xlfn.TEXTJOIN(" ",TRUE,_xlfn._xlws.SORT(_xlfn.TEXTSPLIT(TRIM(UPPER($B34))," ",,TRUE),1,1,TRUE)),puestos!$C$2:$C$324,puestos!$B$2:$B$324),"SIN PUESTO")) -> CHOFER
A35: 10034 | B35: MARCO ANTONIO CADENAS HERNANDEZ | D35: CAHM010308PZ0 | E35: DIEGO ARMANDO SANCHEZ OJEDA | F35: LOGISTICA & OPERACIONES | G35: LOGISTICA | H35: OPERATIVO | I35: 38 | J35: 24/05/2021 | L35: =IF($B35="","",IFERROR(_xlfn.XLOOKUP(_xlfn.TEXTJOIN(" ",TRUE,_xlfn._xlws.SORT(_xlfn.TEXTSPLIT(TRIM(UPPER($B35))," ",,TRUE),1,1,TRUE)),puestos!$C$2:$C$324,puestos!$B$2:$B$324),"SIN PUESTO")) -> AUXILIAR DE BODEGA
A36: 10035 | B36: NANCY ESCALONA MEXICA | C36: nescalona@cafepuntadelcielo.co | D36: EAMN790918SN0 | E36: FELIPE CORTES CAZAREZ | F36: COMERCIAL | G36: COMERCIAL | H36: ADMINISTRATIVO | I36: 34 | J36: 24/05/2021 | L36: =IF($B36="","",IFERROR(_xlfn.XLOOKUP(_xlfn.TEXTJOIN(" ",TRUE,_xlfn._xlws.SORT(_xlfn.TEXTSPLIT(TRIM(UPPER($B36))," ",,TRUE),1,1,TRUE)),puestos!$C$2:$C$324,puestos!$B$2:$B$324),"SIN PUESTO")) -> ESPECIALISTA DE OBZ COMERCIAL
A37: 10036 | B37: NATALIA SOFIA MARTINEZ HERNANDEZ | D37: MAHN740719D64 | E37: LIZBETH RODRIGUEZ RODRIGUEZ | F37: LOGISTICA & OPERACIONES | G37: MONITOREO | H37: OPERATIVO | I37: 38 | J37: 07/06/2021 | L37: =IF($B37="","",IFERROR(_xlfn.XLOOKUP(_xlfn.TEXTJOIN(" ",TRUE,_xlfn._xlws.SORT(_xlfn.TEXTSPLIT(TRIM(UPPER($B37))," ",,TRUE),1,1,TRUE)),puestos!$C$2:$C$324,puestos!$B$2:$B$324),"SIN PUESTO")) -> AUXILIAR DE MONITOREO
A38: 10037 | B38: DIEGO BARRIENTOS RIVERA | C38: dbarrientos@biabrands.co | D38: BARD970115K9A | E38: TANIA CHANTHAL JACINTO TORRES | F38: LEGAL | G38: JURIDICO | H38: ADMINISTRATIVO | I38: 31 | J38: 02/08/2021 | L38: =IF($B38="","",IFERROR(_xlfn.XLOOKUP(_xlfn.TEXTJOIN(" ",TRUE,_xlfn._xlws.SORT(_xlfn.TEXTSPLIT(TRIM(UPPER($B38))," ",,TRUE),1,1,TRUE)),puestos!$C$2:$C$324,puestos!$B$2:$B$324),"SIN PUESTO")) -> ESPECIALISTA JURIDICO
A39: 10038 | B39: CLAUDIA OLIVIA RODRIGUEZ LOPEZ | C39: corodriguez@cafepuntadelcielo.co | D39: ROLC631123SY2 | E39: BRENDA ROJAS MONROY | F39: FINANZAS | G39: CUENTAS POR PAGAR | H39: ADMINISTRATIVO | I39: 38 | J39: 30/08/2021 | L39: =IF($B39="","",IFERROR(_xlfn.XLOOKUP(_xlfn.TEXTJOIN(" ",TRUE,_xlfn._xlws.SORT(_xlfn.TEXTSPLIT(TRIM(UPPER($B39))," ",,TRUE),1,1,TRUE)),puestos!$C$2:$C$324,puestos!$B$2:$B$324),"SIN PUESTO")) -> ANALISTA CUENTAS POR PAGAR
A40: 10039 | B40: RODRIGO EMMANUEL CALIXTRO MORENO | D40: CAMR990929BJ0 | E40: DIEGO ARMANDO SANCHEZ OJEDA | F40: LOGISTICA & OPERACIONES | G40: LOGISTICA | H40: OPERATIVO | I40: 54 | J40: 26/11/2021 | L40: =IF($B40="","",IFERROR(_xlfn.XLOOKUP(_xlfn.TEXTJOIN(" ",TRUE,_xlfn._xlws.SORT(_xlfn.TEXTSPLIT(TRIM(UPPER($B40))," ",,TRUE),1,1,TRUE)),puestos!$C$2:$C$324,puestos!$B$2:$B$324),"SIN PUESTO")) -> AUXILIAR DE BODEGA
...

Sheet puestos
A1: NOMBRE COMPLETO | B1: HOMOLOGACIÓN | C1: CLAVE
A2: GUTIERREZ VITE AUGUSTO ALONSO | B2: COORDINADOR ADMINISTRATIVO TRADE | C2: =IF(A2="","",_xlfn.TEXTJOIN(" ",TRUE,_xlfn._xlws.SORT(_xlfn.TEXTSPLIT(TRIM(UPPER(A2))," ",,TRUE),1,1,TRUE))) -> ALONSO AUGUSTO GUTIERREZ VITE
A3: HERRERA CRUZ ALEJANDRO | B3: CPFR | C3: =IF(A3="","",_xlfn.TEXTJOIN(" ",TRUE,_xlfn._xlws.SORT(_xlfn.TEXTSPLIT(TRIM(UPPER(A3))," ",,TRUE),1,1,TRUE))) -> ALEJANDRO CRUZ HERRERA
A4: GOMEZ REYES RICARDO EMANUEL | B4: CPFR | C4: =IF(A4="","",_xlfn.TEXTJOIN(" ",TRUE,_xlfn._xlws.SORT(_xlfn.TEXTSPLIT(TRIM(UPPER(A4))," ",,TRUE),1,1,TRUE))) -> EMANUEL GOMEZ REYES RICARDO
A5: LOPEZ PALLARES ELIZABETH | B5: EJECUTIVO DE FOOD SERVICE | C5: =IF(A5="","",_xlfn.TEXTJOIN(" ",TRUE,_xlfn._xlws.SORT(_xlfn.TEXTSPLIT(TRIM(UPPER(A5))," ",,TRUE),1,1,TRUE))) -> ELIZABETH LOPEZ PALLARES
A6: ESCALONA MEXICA NANCY | B6: ESPECIALISTA DE OBZ COMERCIAL | C6: =IF(A6="","",_xlfn.TEXTJOIN(" ",TRUE,_xlfn._xlws.SORT(_xlfn.TEXTSPLIT(TRIM(UPPER(A6))," ",,TRUE),1,1,TRUE))) -> ESCALONA MEXICA NANCY
A7: JIMENEZ UGALDE JORGE ANTONIO | B7: GERENTE COMERCIAL | C7: =IF(A7="","",_xlfn.TEXTJOIN(" ",TRUE,_xlfn._xlws.SORT(_xlfn.TEXTSPLIT(TRIM(UPPER(A7))," ",,TRUE),1,1,TRUE))) -> ANTONIO JIMENEZ JORGE UGALDE
A8: CORTES CAZAREZ FELIPE | B8: GERENTE TRADE MARKETING | C8: =IF(A8="","",_xlfn.TEXTJOIN(" ",TRUE,_xlfn._xlws.SORT(_xlfn.TEXTSPLIT(TRIM(UPPER(A8))," ",,TRUE),1,1,TRUE))) -> CAZAREZ CORTES FELIPE
A9: SILVA SANTIAGO ARTURO | B9: KAM MAYOREO Y DISTRIBUIDORES | C9: =IF(A9="","",_xlfn.TEXTJOIN(" ",TRUE,_xlfn._xlws.SORT(_xlfn.TEXTSPLIT(TRIM(UPPER(A9))," ",,TRUE),1,1,TRUE))) -> ARTURO SANTIAGO SILVA
A10: LOPEZ HIDROGO PAULA | B10: KAM NORTE | C10: =IF(A10="","",_xlfn.TEXTJOIN(" ",TRUE,_xlfn._xlws.SORT(_xlfn.TEXTSPLIT(TRIM(UPPER(A10))," ",,TRUE),1,1,TRUE))) -> HIDROGO LOPEZ PAULA
A11: VALENZUELA LOPEZ MAURICIO EDUARDO | B11: KAM VALLE DE MEXICO | C11: =IF(A11="","",_xlfn.TEXTJOIN(" ",TRUE,_xlfn._xlws.SORT(_xlfn.TEXTSPLIT(TRIM(UPPER(A11))," ",,TRUE),1,1,TRUE))) -> EDUARDO LOPEZ MAURICIO VALENZUELA
A12: MEDINA CRUZ FERNANDO | B12: PROMOTOR DE VENTAS | C12: =IF(A12="","",_xlfn.TEXTJOIN(" ",TRUE,_xlfn._xlws.SORT(_xlfn.TEXTSPLIT(TRIM(UPPER(A12))," ",,TRUE),1,1,TRUE))) -> CRUZ FERNANDO MEDINA
A13: ALAMILLA LOPEZ MARGARITA | B13: PROMOTOR DE VENTAS | C13: =IF(A13="","",_xlfn.TEXTJOIN(" ",TRUE,_xlfn._xlws.SORT(_xlfn.TEXTSPLIT(TRIM(UPPER(A13))," ",,TRUE),1,1,TRUE))) -> ALAMILLA LOPEZ MARGARITA
... A324: QUEZADA MENDEZ EDUARDO DANIEL | B324: GERENTE DE REVENUE / BI | C324: =IF(A324="","",_xlfn.TEXTJOIN(" ",TRUE,_xlfn._xlws.SORT(_xlfn.TEXTSPLIT(TRIM(UPPER(A324))," ",,TRUE),1,1,TRUE))) -> DANIEL EDUARDO MENDEZ QUEZADA
